<?xml version="1.0" encoding="utf-8"?>
<!-- This URDF was automatically created by SolidWorks to URDF Exporter! Originally created by Stephen Brawner (brawner@gmail.com) 
     Commit Version: 1.6.0-1-g15f4949  Build Version: 1.6.7594.29634
     For more information, please see http://wiki.ros.org/sw_urdf_exporter -->
<robot
  name="vector_the_arm_description">
  <link
    name="base_link">
    <inertial>
      <origin
        xyz="0.0011876 -0.00024586 -0.0021651"
        rpy="0 0 0" />
      <mass
        value="0.47301" />
      <inertia
        ixx="0.00060142"
        ixy="-7.7811E-06"
        ixz="-4.6303E-06"
        iyy="0.00060151"
        iyz="4.6549E-06"
        izz="0.00099286" />
    </inertial>
    <visual>
      <origin
        xyz="0 0 0"
        rpy="0 0 0" />
      <geometry>
        <mesh
          filename="package://vector_the_arm_description/meshes/base_link.STL" />
      </geometry>
      <material
        name="">
        <color
          rgba="1 1 1 1" />
      </material>
    </visual>
    <collision>
      <origin
        xyz="0 0 0"
        rpy="0 0 0" />
      <geometry>
        <mesh
          filename="package://vector_the_arm_description/meshes/base_link.STL" />
      </geometry>
    </collision>
  </link>
  <link
    name="Link1">
    <inertial>
      <origin
        xyz="-0.00013887 -3.7112E-05 0.037653"
        rpy="0 0 0" />
      <mass
        value="0.16671" />
      <inertia
        ixx="0.00013651"
        ixy="8.7156E-12"
        ixz="6.9648E-08"
        iyy="0.00013384"
        iyz="3.302E-10"
        izz="0.00023132" />
    </inertial>
    <visual>
      <origin
        xyz="0 0 0"
        rpy="0 0 0" />
      <geometry>
        <mesh
          filename="package://vector_the_arm_description/meshes/Link1.STL" />
      </geometry>
      <material
        name="">
        <color
          rgba="1 1 1 1" />
      </material>
    </visual>
    <collision>
      <origin
        xyz="0 0 0"
        rpy="0 0 0" />
      <geometry>
        <mesh
          filename="package://vector_the_arm_description/meshes/Link1.STL" />
      </geometry>
    </collision>
  </link>
  <joint
    name="Joint1"
    type="revolute">
    <origin
      xyz="0 0 0"
      rpy="0 0 3.1416" />
    <parent
      link="base_link" />
    <child
      link="Link1" />
    <axis
      xyz="0 0 1" />
    <limit
      lower="-1.5708"
      upper="1.5708"
      effort="3.0"
      velocity="2.0" />
  </joint>
  <link
    name="Link2">
    <inertial>
      <origin
        xyz="-0.09422 0.003695 -0.022118"
        rpy="0 0 0" />
      <mass
        value="0.12354" />
      <inertia
        ixx="3.6579E-05"
        ixy="-1.8894E-06"
        ixz="3.2641E-07"
        iyy="0.00013792"
        iyz="-6.9245E-08"
        izz="0.00012281" />
    </inertial>
    <visual>
      <origin
        xyz="-0.1347 -0.0128 0"
        rpy="0 0 0" />
      <geometry>
        <mesh
          filename="package://vector_the_arm_description/meshes/Link2.STL" />
      </geometry>
      <material
        name="">
        <color
          rgba="1 1 1 1" />
      </material>
    </visual>
    <collision>
      <origin
        xyz="-0.1347 -0.0128 0"
        rpy="0 0 0" />
      <geometry>
        <mesh
          filename="package://vector_the_arm_description/meshes/Link2.STL" />
      </geometry>
    </collision>
  </link>
  <joint
    name="Joint2"
    type="revolute">
    <origin
      xyz="-0.023219 -0.000282 0.07716"
      rpy="3.1416 1.5708 0" />
    <parent
      link="Link1" />
    <child
      link="Link2" />
    <axis
      xyz="0 0 1" />
    <limit
      lower="-1.82"
      upper="1.82"
      effort="3.0"
      velocity="2.0" />
  </joint>
  <link
    name="Link3">
    <inertial>
      <origin
        xyz="-0.104627 -0.000063 -0.022151"
        rpy="0 0 0" />
      <mass
        value="0.14146" />
      <inertia
        ixx="4.2981E-05"
        ixy="2.0742E-08"
        ixz="3.9424E-07"
        iyy="0.00016334"
        iyz="6.9679E-10"
        izz="0.00015045" />
    </inertial>
    <visual>
      <origin
        xyz="-0.1347 -0.0128 0"
        rpy="0 0 0" />
      <geometry>
        <mesh
          filename="package://vector_the_arm_description/meshes/Link3.STL" />
      </geometry>
      <material
        name="">
        <color
          rgba="1 1 1 1" />
      </material>
    </visual>
    <collision>
      <origin
        xyz="-0.1347 -0.0128 0"
        rpy="0 0 0" />
      <geometry>
        <mesh
          filename="package://vector_the_arm_description/meshes/Link3.STL" />
      </geometry>
    </collision>
  </link>
  <joint
    name="Joint3"
    type="revolute">
    <origin
      xyz="-0.11579 0.029138 0.00049896"
      rpy="0 0 0" />
    <parent
      link="Link2" />
    <child
      link="Link3" />
    <axis
      xyz="0 0 1" />
    <limit
      lower="-1.60"
      upper="1.60"
      effort="3.0"
      velocity="2.0" />
  </joint>
  <link
    name="Link4">
    <inertial>
      <origin
        xyz="-0.057402 -0.000135 -0.022293"
        rpy="0 0 0" />
      <mass
        value="0.18212" />
      <inertia
        ixx="0.00011571"
        ixy="6.8725E-09"
        ixz="4.5323E-06"
        iyy="0.00011637"
        iyz="3.3483E-10"
        izz="8.0361E-05" />
    </inertial>
    <visual>
      <origin
        xyz="-0.1347 -0.0128 0"
        rpy="0 0 0" />
      <geometry>
        <mesh
          filename="package://vector_the_arm_description/meshes/Link4.STL" />
      </geometry>
      <material
        name="">
        <color
          rgba="1 1 1 1" />
      </material>
    </visual>
    <collision>
      <origin
        xyz="-0.1347 -0.0128 0"
        rpy="0 0 0" />
      <geometry>
        <mesh
          filename="package://vector_the_arm_description/meshes/Link4.STL" />
      </geometry>
    </collision>
  </link>
  <joint
    name="Joint4"
    type="revolute">
    <origin
      xyz="-0.15595 -0.000044 -0.043973"
      rpy="3.1416 0 0" />
    <parent
      link="Link3" />
    <child
      link="Link4" />
    <axis
      xyz="0 0 -1" />
    <limit
      lower="-1.55"
      upper="1.55"
      effort="3.0"
      velocity="2.0" />
  </joint>
  <link
    name="Link5">
    <inertial>
      <origin
        xyz="-0.0037812 -7.5442E-05 0.0098443"
        rpy="0 0 0" />
      <mass
        value="0.15471" />
      <inertia
        ixx="0.00011426"
        ixy="2.9963E-08"
        ixz="-2.8589E-05"
        iyy="0.0001344"
        iyz="1.6437E-08"
        izz="7.8003E-05" />
    </inertial>
    <visual>
      <origin
        xyz="0 0 0"
        rpy="0 0 0" />
      <geometry>
        <mesh
          filename="package://vector_the_arm_description/meshes/Link5.STL" />
      </geometry>
      <material
        name="">
        <color
          rgba="1 1 1 1" />
      </material>
    </visual>
    <collision>
      <origin
        xyz="0 0 0"
        rpy="0 0 0" />
      <geometry>
        <mesh
          filename="package://vector_the_arm_description/meshes/Link5.STL" />
      </geometry>
    </collision>
  </link>
  <joint
    name="Joint5"
    type="continuous">
    <origin
      xyz="-0.1347 -0.000286 -0.022559"
      rpy="1.5708 0 1.5708" />
    <parent
      link="Link4" />
    <child
      link="Link5" />
    <axis
      xyz="0 0 1" />
  </joint>
  <link
    name="gripper">
    <inertial>
      <origin
        xyz="-0.039632 -0.0052695 0.00073607"
        rpy="0 0 0" />
      <mass
        value="0.020259" />
      <inertia
        ixx="7.7248E-06"
        ixy="-5.4478E-07"
        ixz="-1.4244E-08"
        iyy="1.3735E-05"
        iyz="-3.6395E-09"
        izz="7.4629E-06" />
    </inertial>
    <visual>
      <origin
        xyz="0.008531 0.002823 0"
        rpy="0 0 0" />
      <geometry>
        <mesh
          filename="package://vector_the_arm_description/meshes/gripper.STL" />
      </geometry>
      <material
        name="">
        <color
          rgba="1 1 1 1" />
      </material>
    </visual>
    <collision>
      <origin
        xyz="0.008531 0.002823 0"
        rpy="0 0 0" />
      <geometry>
        <mesh
          filename="package://vector_the_arm_description/meshes/gripper.STL" />
      </geometry>
    </collision>
  </link>
  <joint
    name="gripper_joint"
    type="revolute">
    <origin
      xyz="0.002823 0 -0.008531"
      rpy="1.5708 -1.5708 0" />
    <parent
      link="Link5" />
    <child
      link="gripper" />
    <axis
      xyz="0 0 1" />
    <!-- 121.8 deg jaw travel: 0 = closed, 2.126 = fully open (servo 6 calibrated 2026-07-07) -->
    <limit
      lower="0"
      upper="2.126"
      effort="1.0"
      velocity="1.0" />
  </joint>
</robot>