<?xml version="1.0" encoding="utf-8"?>
<!-- This URDF was automatically created by SolidWorks to URDF Exporter! Originally created by Stephen Brawner (brawner@gmail.com)
     Commit Version: 1.6.0-1-g15f4949  Build Version: 1.6.7594.29634
     For more information, please see http://wiki.ros.org/sw_urdf_exporter -->
<robot
  name="vector_the_arm_description">
  <link
    name="base_link">
    <inertial>
      <origin
        xyz="0.04017 0.036228 0.089961"
        rpy="0 0 0" />
      <mass
        value="0.47301" />
      <inertia
        ixx="0.00060925"
        ixy="-6.5656E-06"
        ixz="-2.5475E-09"
        iyy="0.00099286"
        iyz="2.1203E-09"
        izz="0.00059369" />
    </inertial>
    <visual>
      <origin
        xyz="0 0 0"
        rpy="0 0 0" />
      <geometry>
        <mesh
          filename="package://vector_the_arm_description/meshes/base_link.STL" />
      </geometry>
      <material
        name="">
        <color
          rgba="1 1 1 1" />
      </material>
    </visual>
    <collision>
      <origin
        xyz="0 0 0"
        rpy="0 0 0" />
      <geometry>
        <mesh
          filename="package://vector_the_arm_description/meshes/base_link.STL" />
      </geometry>
    </collision>
  </link>
  <link
    name="Link1">
    <inertial>
      <origin
        xyz="0 0 0.021148"
        rpy="0 0 0" />
      <mass
        value="0.078819" />
      <inertia
        ixx="0.00010458"
        ixy="0"
        ixz="-5.3187E-21"
        iyy="0.00010458"
        iyz="-1.4648E-20"
        izz="0.00019044" />
    </inertial>
    <visual>
      <origin
        xyz="0 0 0"
        rpy="0 0 0" />
      <geometry>
        <mesh
          filename="package://vector_the_arm_description/meshes/Link1.STL" />
      </geometry>
      <material
        name="">
        <color
          rgba="1 1 1 1" />
      </material>
    </visual>
    <collision>
      <origin
        xyz="0 0 0"
        rpy="0 0 0" />
      <geometry>
        <mesh
          filename="package://vector_the_arm_description/meshes/Link1.STL" />
      </geometry>
    </collision>
  </link>
  <joint
    name="Joint1"
    type="revolute">
    <origin
      xyz="0.039158 -0.09063 0.038393"
      rpy="0 0 0.78837" />
    <parent
      link="base_link" />
    <child
      link="Link1" />
    <axis
      xyz="0 0 1" />
    <limit
      lower="-1.5708"
      upper="1.5708"
      effort="3.0"
      velocity="2.0" />
  </joint>
  <link
    name="Link2">
    <inertial>
      <origin
        xyz="0.049091 0.01203 -0.022092"
        rpy="0 0 0" />
      <mass
        value="0.089999" />
      <inertia
        ixx="2.8107E-05"
        ixy="-1.8894E-06"
        ixz="3.2642E-07"
        iyy="0.0001335"
        iyz="-9.2084E-08"
        izz="0.00011537" />
    </inertial>
    <visual>
      <origin
        xyz="0 0 0"
        rpy="0 0 0" />
      <geometry>
        <mesh
          filename="package://vector_the_arm_description/meshes/Link2.STL" />
      </geometry>
      <material
        name="">
        <color
          rgba="1 1 1 1" />
      </material>
    </visual>
    <collision>
      <origin
        xyz="0 0 0"
        rpy="0 0 0" />
      <geometry>
        <mesh
          filename="package://vector_the_arm_description/meshes/Link2.STL" />
      </geometry>
    </collision>
  </link>
  <joint
    name="Joint2"
    type="revolute">
    <origin
      xyz="-0.023218 0.012518 0.21186"
      rpy="3.1416 1.5708 0" />
    <parent
      link="Link1" />
    <child
      link="Link2" />
    <axis
      xyz="0 0 1" />
    <limit
      lower="-1.82"
      upper="1.82"
      effort="3.0"
      velocity="2.0" />
  </joint>
  <link
    name="Link3">
    <inertial>
      <origin
        xyz="0.042349 0.012701 -0.022133"
        rpy="0 0 0" />
      <mass
        value="0.10792" />
      <inertia
        ixx="3.8564E-05"
        ixy="2.0743E-08"
        ixz="4.1708E-07"
        iyy="0.00015487"
        iyz="6.9966E-10"
        izz="0.00014301" />
    </inertial>
    <visual>
      <origin
        xyz="0 0 0"
        rpy="0 0 0" />
      <geometry>
        <mesh
          filename="package://vector_the_arm_description/meshes/Link3.STL" />
      </geometry>
      <material
        name="">
        <color
          rgba="1 1 1 1" />
      </material>
    </visual>
    <collision>
      <origin
        xyz="0 0 0"
        rpy="0 0 0" />
      <geometry>
        <mesh
          filename="package://vector_the_arm_description/meshes/Link3.STL" />
      </geometry>
    </collision>
  </link>
  <joint
    name="Joint3"
    type="revolute">
    <origin
      xyz="-0.11579 0.029138 0.00049896"
      rpy="0 0 0" />
    <parent
      link="Link2" />
    <child
      link="Link3" />
    <axis
      xyz="0 0 1" />
    <limit
      lower="-1.60"
      upper="1.60"
      effort="3.0"
      velocity="2.0" />
  </joint>
  <link
    name="Link4">
    <inertial>
      <origin
        xyz="0.079969 0.012699 -0.019217"
        rpy="0 0 0" />
      <mass
        value="0.14858" />
      <inertia
        ixx="0.00010827"
        ixy="6.8754E-09"
        ixz="4.5551E-06"
        iyy="0.0001079"
        iyz="3.3593E-10"
        izz="7.5944E-05" />
    </inertial>
    <visual>
      <origin
        xyz="0 0 0"
        rpy="0 0 0" />
      <geometry>
        <mesh
          filename="package://vector_the_arm_description/meshes/Link4.STL" />
      </geometry>
      <material
        name="">
        <color
          rgba="1 1 1 1" />
      </material>
    </visual>
    <collision>
      <origin
        xyz="0 0 0"
        rpy="0 0 0" />
      <geometry>
        <mesh
          filename="package://vector_the_arm_description/meshes/Link4.STL" />
      </geometry>
    </collision>
  </link>
  <joint
    name="Joint4"
    type="revolute">
    <origin
      xyz="-0.15595 0.025556 -0.043973"
      rpy="3.1416 0 0" />
    <parent
      link="Link3" />
    <child
      link="Link4" />
    <axis
      xyz="0 0 1" />
    <limit
      lower="-1.55"
      upper="1.55"
      effort="3.0"
      velocity="2.0" />
  </joint>
</robot>
